# 错误处理目的

## try...catch 是用来处理运行时错误的

这些错误可能是由于代码中的逻辑错误或运行环境的问题（例如，尝试访问不存在的对象属性）。
Promise 的 then...catch 是用来处理异步操作的错误的。Promise 是处理异步操作的一种方式，它可以表示一个最终可能完成（并得到结果）的操作，或者可能失败（并得到一个错误）。
异步与同步：

## try...catch 用于同步代码

这是普通的错误处理机制，一旦出现错误，立即停止当前代码的执行，并跳转到 catch 块。
Promise 的 then...catch 用于处理异步操作。异步操作不会立即返回结果，而是在未来的某个时间点返回。这意味着错误可能在后续的代码执行过程中出现。
使用场景：

## try...catch 通常用于包含可能有错误的代码块

这种结构允许你尝试执行某些代码，并在发生错误时捕获它。
Promise 的 then...catch 通常用于处理异步操作的结果或错误。例如，网络请求、定时器或数据库查询等都可能是异步的，并返回一个 Promise。
错误传播：

## try...catch 中，一旦捕获到错误，该错误会被处理，并停止传播

如果没有 catch 块来捕获错误，错误将继续向上传播，直到被某个上层作用域的 catch 块捕获，或者如果没有的话，程序将终止。
在 Promise 的 then...catch 中，错误会被捕获并处理，但不会阻止 Promise 链的继续执行。如果在 then 后面还有更多的链式调用或 finally 块，它们仍然会执行。

# 错误处理策略

## try...catch 中，你可以在 catch 块中添加逻辑来处理错误（例如，记录日志、向用户显示错误消息等）

在 Promise 的 then...catch 中，你也可以添加逻辑来处理错误，但通常的做法是使用 .catch() 来处理特定类型的错误或对错误进行分类处理。
嵌套与链式调用：

## try...catch 可以嵌套使用，以捕获不同层次的异常

这使得你可以在更细粒度上控制异常的处理。
Promise 的链式调用允许你在一个 Promise 上链接多个操作。如果在链中的任何一个操作失败，后续的操作将不会被执行。但是，每个单独的操作（无论是成功还是失败）都会继续其自己的异常处理路径。如果一个操作失败，并且后面有 .catch() 处理程序，那么 .catch() 将捕获这个错误，而不是允许它传播到链中的下一个操作。
